Workbook
Name Family: [1]Coefficients!$AI$9:$AI$10
Name FamSelect: [1]Coefficients!$AJ$8
Name Princeton: [1]Coefficients!$AI$13:$AI$16
Name Sex: [1]Coefficients!$AI$29:$AI$31
Name UN: [1]Coefficients!$AI$17:$AI$21
Name Variant: [1]Coefficients!$AI$24:$AI$26

Sheet Decrementos Múltiples
B2: Hombres, 2019
B3: Age x | C3: n | D3: nDx | E3: nDxi | I3: nqx | K3: e0 | M3: nqx_i | O3: ndx_i | Q3: L | R3: T | S3: e0_i | T3: diff
B4: 0 | C4: 1 | D4: ='Defunciones generales'!D21 -> 374.29416 | E4: =Homicidios!D1218 -> 2 | F4: =(D4-E4)/D4 -> 0.99465661 | G4: =LT!H21 -> 100000 | H4: =1-LT!F21 -> 0.977164 | I4: =1-H4 -> 0.022836 | J4: =LT!G2 -> 0.12 | K4: =LT!L21 -> 64.93 | L4: =H4^F4 -> 0.97728463 | M4: =1-L4 -> 0.022715375 | N4: 100000 | O4: =N4*M4 -> 2271.5375 | P4: =C4+(F4*(I4/M4)*(J4-C4)) -> 0.1200541 | Q4: =(C4*N5)+(P4*O4) -> 98001.17 | R4: =R5+Q4 -> 6513113.7 | S4: =R4/N4 -> 65.131137 | T4: =S4-K4 -> 0.20113667
B5: 1 | C5: 4 | D5: ='Defunciones generales'!D22 -> 68.043432 | E5: =Homicidios!D1219 -> 0 | F5: =(D5-E5)/D5 -> 1 | G5: =LT!H22 -> 97716 | H5: =1-LT!F22 -> 0.996291 | I5: =1-H5 -> 0.003709 | J5: =LT!G3 -> 1.57 | K5: =LT!L22 -> 65.44 | L5: =H5^F5 -> 0.996291 | M5: =1-L5 -> 0.003709 | N5: =N4*L4 -> 97728.463 | O5: =N5*M5 -> 362.47487 | P5: =C5+(F5*(I5/M5)*(J5-C5)) -> 1.57 | Q5: =(C5*N6)+(P5*O5) -> 390033.04 | R5: =R6+Q5 -> 6415112.5 | S5: =R5/N5 -> 65.642212 | T5: =S5-K5 -> 0.20221244 | V5: Número de años que se espera que viva un hombre de 0 años hasta llegar a los 85 años.
B6: 5 | C6: 5 | D6: ='Defunciones generales'!D23 -> 36.01918 | E6: =Homicidios!D1220 -> 0 | F6: =(D6-E6)/D6 -> 1 | G6: =LT!H23 -> 97354 | H6: =1-LT!F23 -> 0.998085 | I6: =1-H6 -> 0.001915 | J6: =LT!G4 -> 2.5 | K6: =LT!L23 -> 61.68 | L6: =H6^F6 -> 0.998085 | M6: =1-L6 -> 0.001915 | N6: =N5*L5 -> 97365.988 | O6: =N6*M6 -> 186.45587 | P6: =C6+(F6*(I6/M6)*(J6-C6)) -> 2.5 | Q6: =(C6*N7)+(P6*O6) -> 486363.8 | R6: =R7+Q6 -> 6025079.5 | S6: =R6/N6 -> 61.880741 | T6: =S6-K6 -> 0.20074098
B7: 10 | C7: 5 | D7: ='Defunciones generales'!D24 -> 47.030129 | E7: =Homicidios!D1221 -> 0 | F7: =(D7-E7)/D7 -> 1 | G7: =LT!H24 -> 97168 | H7: =1-LT!F24 -> 0.997549 | I7: =1-H7 -> 0.002451 | J7: =LT!G5 -> 2.5 | K7: =LT!L24 -> 56.79 | L7: =H7^F7 -> 0.997549 | M7: =1-L7 -> 0.002451 | N7: =N6*L6 -> 97179.532 | O7: =N7*M7 -> 238.18703 | P7: =(((-5/24)*O6)+((2.5)*O7)+((5/24)*O8))/O7 -> 2.8898415 | Q7: =(C7*N8)+(P7*O7) -> 485395.05 | R7: =R8+Q7 -> 5538715.7 | S7: =R7/N7 -> 56.994673 | T7: =S7-K7 -> 0.20467327
B8: 15 | C8: 5 | D8: ='Defunciones generales'!D25 -> 132.07314 | E8: =Homicidios!D1222 -> 2 | F8: =(D8-E8)/D8 -> 0.98485688 | G8: =LT!H25 -> 96929 | H8: =1-LT!F25 -> 0.993379 | I8: =1-H8 -> 0.006621 | J8: =LT!G6 -> 2.5 | K8: =LT!L25 -> 51.93 | L8: =H8^F8 -> 0.99347893 | M8: =1-L8 -> 0.006521065 | N8: =N7*L7 -> 96941.345 | O8: =N8*M8 -> 632.16081 | P8: =(((-5/24)*O7)+((2.5)*O8)+((5/24)*O9))/O8 -> 2.8018371 | Q8: =(C8*N9)+(P8*O8) -> 483317.13 | R8: =R9+Q8 -> 5053320.6 | S8: =R8/N8 -> 52.12761 | T8: =S8-K8 -> 0.19761005 | V8: Sin COVID | W8: Con COVID
B9: 20 | C9: 5 | D9: ='Defunciones generales'!D26 -> 240.14853 | E9: =Homicidios!D1223 -> 0 | F9: =(D9-E9)/D9 -> 1 | G9: =LT!H26 -> 96288 | H9: =1-LT!F26 -> 0.988017 | I9: =1-H9 -> 0.011983 | J9: =LT!G7 -> 2.5 | K9: =LT!L26 -> 47.26 | L9: =H9^F9 -> 0.988017 | M9: =1-L9 -> 0.011983 | N9: =N8*L8 -> 96309.184 | O9: =N9*M9 -> 1154.073 | P9: =(((-5/24)*O8)+((2.5)*O9)+((5/24)*O10))/O9 -> 2.6478143 | Q9: =(C9*N10)+(P9*O9) -> 478831.33 | R9: =R10+Q9 -> 4570003.5 | S9: =R9/N9 -> 47.451378 | T9: =S9-K9 -> 0.19137793 | V9: =([2]TV!M53-[2]TV!M71)/[2]TV!J53 -> 66.401396 | W9: =(R4-R22)/N4 -> 64.778306
B10: 25 | C10: 5 | D10: ='Defunciones generales'!D27 -> 301.19286 | E10: =Homicidios!D1224 -> 14 | F10: =(D10-E10)/D10 -> 0.95351815 | G10: =LT!H27 -> 95134 | H10: =1-LT!F27 -> 0.984014 | I10: =1-H10 -> 0.015986 | J10: =LT!G8 -> 2.5 | K10: =LT!L27 -> 42.8 | L10: =H10^F10 -> 0.98475136 | M10: =1-L10 -> 0.015248636 | N10: =N9*L9 -> 95155.111 | O10: =N10*M10 -> 1450.9857 | P10: =(((-5/24)*O9)+((2.5)*O10)+((5/24)*O11))/O10 -> 2.5975696 | Q10: =(C10*N11)+(P10*O10) -> 472289.66 | R10: =R11+Q10 -> 4091172.2 | S10: =R10/N10 -> 42.994771 | T10: =S10-K10 -> 0.1947705 | V10: Diff | W10: =W9-V9 -> -1.6230904
B11: 30 | C11: 5 | D11: ='Defunciones generales'!D28 -> 364.23558 | E11: =Homicidios!D1225 -> 16 | F11: =(D11-E11)/D11 -> 0.95607239 | G11: =LT!H28 -> 93613 | H11: =1-LT!F28 -> 0.979542 | I11: =1-H11 -> 0.020458 | J11: =LT!G9 -> 2.5 | K11: =LT!L28 -> 38.45 | L11: =H11^F11 -> 0.98043182 | M11: =1-L11 -> 0.019568181 | N11: =N10*L10 -> 93704.125 | O11: =N11*M11 -> 1833.6193 | P11: =(((-5/24)*O10)+((2.5)*O11)+((5/24)*O12))/O11 -> 2.6225402 | Q11: =(C11*N12)+(P11*O11) -> 464161.27 | R11: =R12+Q11 -> 3618882.5 | S11: =R11/N11 -> 38.620311 | T11: =S11-K11 -> 0.17031137
B12: 35 | C12: 5 | D12: ='Defunciones generales'!D29 -> 478.30148 | E12: =Homicidios!D1226 -> 10 | F12: =(D12-E12)/D12 -> 0.97909268 | G12: =LT!H29 -> 91698 | H12: =1-LT!F29 -> 0.971887 | I12: =1-H12 -> 0.028113 | J12: =LT!G10 -> 2.5 | K12: =LT!L29 -> 34.2 | L12: =H12^F12 -> 0.9724666 | M12: =1-L12 -> 0.0275334 | N12: =N11*L11 -> 91870.506 | O12: =N12*M12 -> 2529.5074 | P12: =(((-5/24)*O11)+((2.5)*O12)+((5/24)*O13))/O12 -> 2.6065315 | Q12: =(C12*N13)+(P12*O12) -> 453298.23 | R12: =R13+Q12 -> 3154721.2 | S12: =R12/N12 -> 34.338781 | T12: =S12-K12 -> 0.13878142
B13: 40 | C13: 5 | D13: ='Defunciones generales'!D30 -> 548.33017 | E13: =Homicidios!D1227 -> 6 | F13: =(D13-E13)/D13 -> 0.98905769 | G13: =LT!H30 -> 89120 | H13: =1-LT!F30 -> 0.964618 | I13: =1-H13 -> 0.035382 | J13: =LT!G11 -> 2.5 | K13: =LT!L30 -> 30.12 | L13: =H13^F13 -> 0.9649983 | M13: =1-L13 -> 0.035001696 | N13: =N12*L12 -> 89340.999 | O13: =N13*M13 -> 3127.0864 | P13: =(((-5/24)*O12)+((2.5)*O13)+((5/24)*O14))/O13 -> 2.5997217 | Q13: =(C13*N14)+(P13*O13) -> 439199.12 | R13: =R14+Q13 -> 2701423 | S13: =R13/N13 -> 30.237215 | T13: =S13-K13 -> 0.11721509
B14: 45 | C14: 5 | D14: ='Defunciones generales'!D31 -> 671.42929 | E14: =Homicidios!D1228 -> 16 | F14: =(D14-E14)/D14 -> 0.97617024 | G14: =LT!H31 -> 85967 | H14: =1-LT!F31 -> 0.952186 | I14: =1-H14 -> 0.047814 | J14: =LT!G12 -> 2.5 | K14: =LT!L31 -> 26.13 | L14: =H14^F14 -> 0.95329836 | M14: =1-L14 -> 0.046701639 | N14: =N13*L13 -> 86213.912 | O14: =N14*M14 -> 4026.331 | P14: =(((-5/24)*O13)+((2.5)*O14)+((5/24)*O15))/O14 -> 2.6206579 | Q14: =(C14*N15)+(P14*O14) -> 421489.54 | R14: =R15+Q14 -> 2262223.9 | S14: =R14/N14 -> 26.239662 | T14: =S14-K14 -> 0.10966155
B15: 50 | C15: 5 | D15: ='Defunciones generales'!D32 -> 786.47466 | E15: =Homicidios!D1229 -> 8 | F15: =(D15-E15)/D15 -> 0.98982803 | G15: =LT!H32 -> 81856 | H15: =1-LT!F32 -> 0.93292 | I15: =1-H15 -> 0.06708 | J15: =LT!G13 -> 2.5 | K15: =LT!L32 -> 22.32 | L15: =H15^F15 -> 0.93357915 | M15: =1-L15 -> 0.066420846 | N15: =N14*L14 -> 82187.581 | O15: =N15*M15 -> 5458.9687 | P15: =(((-5/24)*O14)+((2.5)*O15)+((5/24)*O16))/O15 -> 2.6362219 | Q15: =(C15*N16)+(P15*O15) -> 398034.12 | R15: =R16+Q15 -> 1840734.3 | S15: =R15/N15 -> 22.396745 | T15: =S15-K15 -> 0.076745444
B16: 55 | C16: 5 | D16: ='Defunciones generales'!D33 -> 1001.6084 | E16: =Homicidios!D1230 -> 6 | F16: =(D16-E16)/D16 -> 0.99400963 | G16: =LT!H33 -> 76365 | H16: =1-LT!F33 -> 0.900439 | I16: =1-H16 -> 0.099561 | J16: =LT!G14 -> 2.5 | K16: =LT!L33 -> 18.75 | L16: =H16^F16 -> 0.90100486 | M16: =1-L16 -> 0.098995142 | N16: =N15*L15 -> 76728.612 | O16: =N16*M16 -> 7595.7599 | P16: =(((-5/24)*O15)+((2.5)*O16)+((5/24)*O17))/O16 -> 2.5991891 | Q16: =(C16*N17)+(P16*O16) -> 365407.08 | R16: =R17+Q16 -> 1442700.2 | S16: =R16/N16 -> 18.802637 | T16: =S16-K16 -> 0.052636626
B17: 60 | C17: 5 | D17: ='Defunciones generales'!D34 -> 1128.6799 | E17: =Homicidios!D1231 -> 4 | F17: =(D17-E17)/D17 -> 0.99645604 | G17: =LT!H34 -> 68762 | H17: =1-LT!F34 -> 0.868291 | I17: =1-H17 -> 0.131709 | J17: =LT!G15 -> 2.5 | K17: =LT!L34 -> 15.54 | L17: =H17^F17 -> 0.8687257 | M17: =1-L17 -> 0.1312743 | N17: =N16*L16 -> 69132.853 | O17: =N17*M17 -> 9075.3671 | P17: =(((-5/24)*O16)+((2.5)*O17)+((5/24)*O18))/O17 -> 2.5738589 | Q17: =(C17*N18)+(P17*O17) -> 323646.14 | R17: =R18+Q17 -> 1077293.1 | S17: =R17/N17 -> 15.582941 | T17: =S17-K17 -> 0.042940678
B18: 65 | C18: 5 | D18: ='Defunciones generales'!D35 -> 1316.8323 | E18: =Homicidios!D1232 -> 4 | F18: =(D18-E18)/D18 -> 0.99696241 | G18: =LT!H35 -> 59706 | H18: =1-LT!F35 -> 0.819457 | I18: =1-H18 -> 0.180543 | J18: =LT!G16 -> 2.5 | K18: =LT!L35 -> 12.52 | L18: =H18^F18 -> 0.81995278 | M18: =1-L18 -> 0.18004722 | N18: =N17*L17 -> 60057.485 | O18: =N18*M18 -> 10813.183 | P18: =(((-5/24)*O17)+((2.5)*O18)+((5/24)*O19))/O18 -> 2.5793896 | Q18: =(C18*N19)+(P18*O18) -> 274112.92 | R18: =R19+Q18 -> 753647 | S18: =R18/N18 -> 12.54876 | T18: =S18-K18 -> 0.028760468
B19: 70 | C19: 5 | D19: ='Defunciones generales'!D36 -> 1530.9641 | E19: =Homicidios!D1233 -> 0 | F19: =(D19-E19)/D19 -> 1 | G19: =LT!H36 -> 48926 | H19: =1-LT!F36 -> 0.732031 | I19: =1-H19 -> 0.267969 | J19: =LT!G17 -> 2.5 | K19: =LT!L36 -> 9.73 | L19: =H19^F19 -> 0.732031 | M19: =1-L19 -> 0.267969 | N19: =N18*L18 -> 49244.302 | O19: =N19*M19 -> 13195.946 | P19: =(((-5/24)*O18)+((2.5)*O19)+((5/24)*O20))/O19 -> 2.5372237 | Q19: =(C19*N20)+(P19*O19) -> 213722.85 | R19: =R20+Q19 -> 479534.08 | S19: =R19/N19 -> 9.7378591 | T19: =S19-K19 -> 0.0078591339
B20: 75 | C20: 5 | D20: ='Defunciones generales'!D37 -> 1500.9354 | E20: =Homicidios!D1234 -> 2 | F20: =(D20-E20)/D20 -> 0.9986675 | G20: =LT!H37 -> 35816 | H20: =1-LT!F37 -> 0.634246 | I20: =1-H20 -> 0.365754 | J20: =LT!G18 -> 2.5 | K20: =LT!L37 -> 7.38 | L20: =H20^F20 -> 0.63463092 | M20: =1-L20 -> 0.36536908 | N20: =N19*L19 -> 36048.356 | O20: =N20*M20 -> 13170.954 | P20: =(((-5/24)*O19)+((2.5)*O20)+((5/24)*O21))/O20 -> 2.4874612 | Q20: =(C20*N21)+(P20*O20) -> 147149.24 | R20: =R21+Q20 -> 265811.23 | S20: =R20/N20 -> 7.3737408 | T20: =S20-K20 -> -0.0062592309
B21: 80 | C21: 5 | D21: ='Defunciones generales'!D38 -> 1529.963 | E21: =Homicidios!D1235 -> 0 | F21: =(D21-E21)/D21 -> 1 | G21: =LT!H38 -> 22716 | H21: =1-LT!F38 -> 0.457839 | I21: =1-H21 -> 0.542161 | J21: =LT!G19 -> 2.5 | K21: =LT!L38 -> 5.19 | L21: =H21^F21 -> 0.457839 | M21: =1-L21 -> 0.542161 | N21: =N20*L20 -> 22877.401 | O21: =N21*M21 -> 12403.235 | P21: =C21+(F21*(I21/M21)*(J21-C21)) -> 2.5 | Q21: =(C21*N22)+(P21*O21) -> 83378.919 | R21: =R22+Q21 -> 118661.99 | S21: =R21/N21 -> 5.1868648 | T21: =S21-K21 -> -0.0031352436
B22: 85 | C22: 5 | D22: ='Defunciones generales'!D39 -> 2432.5226 | E22: =Homicidios!D1236 -> 2 | F22: =(D22-E22)/D22 -> 0.99917781 | G22: =LT!H39 -> 10400 | H22: =1-LT!F39 -> 0 | I22: =1-H22 -> 1 | J22: =LT!G20 -> NA | K22: =LT!L39 -> 3.37 | L22: =H22^F22 -> 0 | M22: =1-L22 -> 1 | N22: =N21*L21 -> 10474.166 | O22: =N22*M22 -> 10474.166 | P22: =K22/F22 -> 3.3727731 | Q22: =N22/LT!E39 -> 35283.067 | R22: =Q22 -> 35283.067 | S22: =R22/N22 -> 3.3685799 | T22: =S22-K22 -> -0.0014200922
B24: Mujeres, 2019
B26: Age x | C26: n | D26: nDx | E26: nDxi | I26: nqx | K26: e0 | M26: nqx_i | O26: ndx_i | Q26: L | R26: T | S26: e0_i | T26: diff | AA26: Hombres | AB26: Mujeres
B27: 0 | C27: 1 | D27: ='Defunciones generales'!D78 -> 319.95079 | E27: =Homicidios!D553 -> 0 | F27: =(D27-E27)/D27 -> 1 | G27: =LT!H78 -> 100000 | H27: =1-LT!F78 -> 0.979935 | I27: =1-H27 -> 0.020065 | J27: =LT!G78 -> 0.11 | K27: =LT!L78 -> 70.39 | L27: =H27^F27 -> 0.979935 | M27: =1-L27 -> 0.020065 | N27: 100000 | O27: =N27*M27 -> 2006.5 | P27: =C27+(F27*(I27/M27)*(J27-C27)) -> 0.11 | Q27: =(C27*N28)+(P27*O27) -> 98214.215 | R27: =R28+Q27 -> 7046527.3 | S27: =R27/N27 -> 70.465273 | T27: =S27-K27 -> 0.075273147 | Z27: Sin homicidios | AA27: =S4 -> 65.131137 | AB27: =S27 -> 70.465273
B28: 1 | C28: 4 | D28: ='Defunciones generales'!D79 -> 63.005222 | E28: =Homicidios!D554 -> 0 | F28: =(D28-E28)/D28 -> 1 | G28: =LT!H79 -> 97994 | H28: =1-LT!F79 -> 0.996458 | I28: =1-H28 -> 0.003542 | J28: =LT!G79 -> 1.49 | K28: =LT!L79 -> 70.82 | L28: =H28^F28 -> 0.996458 | M28: =1-L28 -> 0.003542 | N28: =N27*L27 -> 97993.5 | O28: =N28*M28 -> 347.09298 | P28: =C28+(F28*(I28/M28)*(J28-C28)) -> 1.49 | Q28: =(C28*N29)+(P28*O28) -> 391102.8 | R28: =R29+Q28 -> 6948313.1 | S28: =R28/N28 -> 70.905857 | T28: =S28-K28 -> 0.085857018 | V28: Número de años que se espera que viva una mujer de 0 años hasta llegar a los 85 años. | Z28: Con homicidios | AA28: =K4 -> 64.93 | AB28: =K27 -> 70.39
B29: 5 | C29: 5 | D29: ='Defunciones generales'!D80 -> 29.001516 | E29: =Homicidios!D555 -> 0 | F29: =(D29-E29)/D29 -> 1 | G29: =LT!H80 -> 97646 | H29: =1-LT!F80 -> 0.998429 | I29: =1-H29 -> 0.001571 | J29: =LT!G80 -> 2.5 | K29: =LT!L80 -> 67.07 | L29: =H29^F29 -> 0.998429 | M29: =1-L29 -> 0.001571 | N29: =N28*L28 -> 97646.407 | O29: =N29*M29 -> 153.40251 | P29: =C29+(F29*(I29/M29)*(J29-C29)) -> 2.5 | Q29: =(C29*N30)+(P29*O29) -> 487848.53 | R29: =R30+Q29 -> 6557210.3 | S29: =R29/N29 -> 67.152602 | T29: =S29-K29 -> 0.082601954 | AA29: =AA27-AA28 -> 0.20113667 | AB29: =AB27-AB28 -> 0.075273147
B30: 10 | C30: 5 | D30: ='Defunciones generales'!D81 -> 44.004211 | E30: =Homicidios!D556 -> 0 | F30: =(D30-E30)/D30 -> 1 | G30: =LT!H81 -> 97493 | H30: =1-LT!F81 -> 0.997643 | I30: =1-H30 -> 0.002357 | J30: =LT!G81 -> 2.5 | K30: =LT!L81 -> 62.17 | L30: =H30^F30 -> 0.997643 | M30: =1-L30 -> 0.002357 | N30: =N29*L29 -> 97493.005 | O30: =N30*M30 -> 229.79101 | P30: =(((-5/24)*O29)+((2.5)*O30)+((5/24)*O31))/O30 -> 2.6966266 | Q30: =(C30*N31)+(P30*O30) -> 486935.73 | R30: =R31+Q30 -> 6069361.8 | S30: =R30/N30 -> 62.254331 | T30: =S30-K30 -> 0.084331008
B31: 15 | C31: 5 | D31: ='Defunciones generales'!D82 -> 74.006738 | E31: =Homicidios!D557 -> 0 | F31: =(D31-E31)/D31 -> 1 | G31: =LT!H82 -> 97263 | H31: =1-LT!F82 -> 0.996193 | I31: =1-H31 -> 0.003807 | J31: =LT!G82 -> 2.5 | K31: =LT!L82 -> 57.31 | L31: =H31^F31 -> 0.996193 | M31: =1-L31 -> 0.003807 | N31: =N30*L30 -> 97263.214 | O31: =N31*M31 -> 370.28105 | P31: =(((-5/24)*O30)+((2.5)*O31)+((5/24)*O32))/O31 -> 2.6396359 | Q31: =(C31*N32)+(P31*O31) -> 485442.07 | R31: =R32+Q31 -> 5582426 | S31: =R31/N31 -> 57.39504 | T31: =S31-K31 -> 0.085040169 | V31: Sin COVID | W31: Con COVID
B32: 20 | C32: 5 | D32: ='Defunciones generales'!D83 -> 98.008928 | E32: =Homicidios!D558 -> 0 | F32: =(D32-E32)/D32 -> 1 | G32: =LT!H83 -> 96893 | H32: =1-LT!F83 -> 0.995067 | I32: =1-H32 -> 0.004933 | J32: =LT!G83 -> 2.5 | K32: =LT!L83 -> 52.52 | L32: =H32^F32 -> 0.995067 | M32: =1-L32 -> 0.004933 | N32: =N31*L31 -> 96892.932 | O32: =N32*M32 -> 477.97284 | P32: =(((-5/24)*O31)+((2.5)*O32)+((5/24)*O33))/O32 -> 2.560242 | Q32: =(C32*N33)+(P32*O32) -> 483298.52 | R32: =R33+Q32 -> 5096984 | S32: =R32/N32 -> 52.604291 | T32: =S32-K32 -> 0.084290609 | V32: =([2]TV!M29-[2]TV!M47)/[2]TV!J29 -> 73.3257 | W32: =(R27-R45)/N27 -> 69.847801
B33: 25 | C33: 5 | D33: ='Defunciones generales'!D84 -> 101.00893 | E33: =Homicidios!D559 -> 0 | F33: =(D33-E33)/D33 -> 1 | G33: =LT!H84 -> 96415 | H33: =1-LT!F84 -> 0.994726 | I33: =1-H33 -> 0.005274 | J33: =LT!G84 -> 2.5 | K33: =LT!L84 -> 47.77 | L33: =H33^F33 -> 0.994726 | M33: =1-L33 -> 0.005274 | N33: =N32*L32 -> 96414.96 | O33: =N33*M33 -> 508.4925 | P33: =(((-5/24)*O32)+((2.5)*O33)+((5/24)*O34))/O33 -> 2.6582933 | Q33: =(C33*N34)+(P33*O33) -> 480884.06 | R33: =R34+Q33 -> 4613685.5 | S33: =R33/N33 -> 47.852382 | T33: =S33-K33 -> 0.082381734 | V33: Diff | W33: =W32-V32 -> -3.4778988
B34: 30 | C34: 5 | D34: ='Defunciones generales'!D85 -> 170.01567 | E34: =Homicidios!D560 -> 2 | F34: =(D34-E34)/D34 -> 0.98823638 | G34: =LT!H85 -> 95907 | H34: =1-LT!F85 -> 0.990881 | I34: =1-H34 -> 0.009119 | J34: =LT!G85 -> 2.5 | K34: =LT!L85 -> 43.01 | L34: =H34^F34 -> 0.99098779 | M34: =1-L34 -> 0.0090122124 | N34: =N33*L33 -> 95906.467 | O34: =N34*M34 -> 864.32945 | P34: =(((-5/24)*O33)+((2.5)*O34)+((5/24)*O35))/O34 -> 2.61362 | Q34: =(C34*N35)+(P34*O34) -> 477469.72 | R34: =R35+Q34 -> 4132801.4 | S34: =R34/N34 -> 43.091999 | T34: =S34-K34 -> 0.081999098
B35: 35 | C35: 5 | D35: ='Defunciones generales'!D86 -> 185.01583 | E35: =Homicidios!D561 -> 2 | F35: =(D35-E35)/D35 -> 0.98919011 | G35: =LT!H86 -> 95032 | H35: =1-LT!F86 -> 0.989578 | I35: =1-H35 -> 0.010422 | J35: =LT!G86 -> 2.5 | K35: =LT!L86 -> 38.38 | L35: =H35^F35 -> 0.98969008 | M35: =1-L35 -> 0.010309922 | N35: =N34*L34 -> 95042.138 | O35: =N35*M35 -> 979.87704 | P35: =(((-5/24)*O34)+((2.5)*O35)+((5/24)*O36))/O35 -> 2.6451853 | Q35: =(C35*N36)+(P35*O35) -> 472903.26 | R35: =R36+Q35 -> 3655331.7 | S35: =R35/N35 -> 38.460116 | T35: =S35-K35 -> 0.080116399
B36: 40 | C36: 5 | D36: ='Defunciones generales'!D87 -> 273.02308 | E36: =Homicidios!D562 -> 2 | F36: =(D36-E36)/D36 -> 0.99267461 | G36: =LT!H87 -> 94042 | H36: =1-LT!F87 -> 0.983431 | I36: =1-H36 -> 0.016569 | J36: =LT!G87 -> 2.5 | K36: =LT!L87 -> 33.76 | L36: =H36^F36 -> 0.98355137 | M36: =1-L36 -> 0.016448629 | N36: =N35*L35 -> 94062.261 | O36: =N36*M36 -> 1547.1953 | P36: =(((-5/24)*O35)+((2.5)*O36)+((5/24)*O37))/O36 -> 2.7004322 | Q36: =(C36*N37)+(P36*O36) -> 466753.42 | R36: =R37+Q36 -> 3182428.4 | S36: =R36/N36 -> 33.833212 | T36: =S36-K36 -> 0.073212139
B37: 45 | C37: 5 | D37: ='Defunciones generales'!D88 -> 400.03251 | E37: =Homicidios!D563 -> 0 | F37: =(D37-E37)/D37 -> 1 | G37: =LT!H88 -> 92483 | H37: =1-LT!F88 -> 0.973319 | I37: =1-H37 -> 0.026681 | J37: =LT!G88 -> 2.5 | K37: =LT!L88 -> 29.29 | L37: =H37^F37 -> 0.973319 | M37: =1-L37 -> 0.026681 | N37: =N36*L36 -> 92515.065 | O37: =N37*M37 -> 2468.3945 | P37: =(((-5/24)*O36)+((2.5)*O37)+((5/24)*O38))/O37 -> 2.6724422 | Q37: =(C37*N38)+(P37*O37) -> 456830 | R37: =R38+Q37 -> 2715675 | S37: =R37/N37 -> 29.353868 | T37: =S37-K37 -> 0.063867769
B38: 50 | C38: 5 | D38: ='Defunciones generales'!D89 -> 513.04582 | E38: =Homicidios!D564 -> 0 | F38: =(D38-E38)/D38 -> 1 | G38: =LT!H89 -> 90016 | H38: =1-LT!F89 -> 0.960128 | I38: =1-H38 -> 0.039872 | J38: =LT!G89 -> 2.5 | K38: =LT!L89 -> 25.02 | L38: =H38^F38 -> 0.960128 | M38: =1-L38 -> 0.039872 | N38: =N37*L37 -> 90046.671 | O38: =N38*M38 -> 3590.3409 | P38: =(((-5/24)*O37)+((2.5)*O38)+((5/24)*O39))/O38 -> 2.6623874 | Q38: =(C38*N39)+(P38*O38) -> 441840.53 | R38: =R39+Q38 -> 2258845 | S38: =R38/N38 -> 25.085269 | T38: =S38-K38 -> 0.065269413
B39: 55 | C39: 5 | D39: ='Defunciones generales'!D90 -> 667.05862 | E39: =Homicidios!D565 -> 0 | F39: =(D39-E39)/D39 -> 1 | G39: =LT!H90 -> 86427 | H39: =1-LT!F90 -> 0.93908 | I39: =1-H39 -> 0.06092 | J39: =LT!G90 -> 2.5 | K39: =LT!L90 -> 20.96 | L39: =H39^F39 -> 0.93908 | M39: =1-L39 -> 0.06092 | N39: =N38*L38 -> 86456.33 | O39: =N39*M39 -> 5266.9196 | P39: =(((-5/24)*O38)+((2.5)*O39)+((5/24)*O40))/O39 -> 2.6814285 | Q39: =(C39*N40)+(P39*O39) -> 420069.92 | R39: =R40+Q39 -> 1817004.5 | S39: =R39/N39 -> 21.016442 | T39: =S39-K39 -> 0.05644229
B40: 60 | C40: 5 | D40: ='Defunciones generales'!D91 -> 950.07951 | E40: =Homicidios!D566 -> 0 | F40: =(D40-E40)/D40 -> 1 | G40: =LT!H91 -> 81162 | H40: =1-LT!F91 -> 0.899284 | I40: =1-H40 -> 0.100716 | J40: =LT!G91 -> 2.5 | K40: =LT!L91 -> 17.15 | L40: =H40^F40 -> 0.899284 | M40: =1-L40 -> 0.100716 | N40: =N39*L39 -> 81189.41 | O40: =N40*M40 -> 8177.0727 | P40: =(((-5/24)*O39)+((2.5)*O40)+((5/24)*O41))/O40 -> 2.6323369 | Q40: =(C40*N41)+(P40*O40) -> 386586.5 | R40: =R41+Q40 -> 1396934.6 | S40: =R40/N40 -> 17.205871 | T40: =S40-K40 -> 0.05587135
B41: 65 | C41: 5 | D41: ='Defunciones generales'!D92 -> 1134.0942 | E41: =Homicidios!D567 -> 0 | F41: =(D41-E41)/D41 -> 1 | G41: =LT!H92 -> 72987 | H41: =1-LT!F92 -> 0.856721 | I41: =1-H41 -> 0.143279 | J41: =LT!G92 -> 2.5 | K41: =LT!L92 -> 13.8 | L41: =H41^F41 -> 0.856721 | M41: =1-L41 -> 0.143279 | N41: =N40*L40 -> 73012.338 | O41: =N41*M41 -> 10461.135 | P41: =(((-5/24)*O40)+((2.5)*O41)+((5/24)*O42))/O41 -> 2.607406 | Q41: =(C41*N42)+(P41*O41) -> 340032.44 | R41: =R42+Q41 -> 1010348.1 | S41: =R41/N41 -> 13.838046 | T41: =S41-K41 -> 0.038045502
B42: 70 | C42: 5 | D42: ='Defunciones generales'!D93 -> 1318.1016 | E42: =Homicidios!D568 -> 0 | F42: =(D42-E42)/D42 -> 1 | G42: =LT!H93 -> 62530 | H42: =1-LT!F93 -> 0.783053 | I42: =1-H42 -> 0.216947 | J42: =LT!G93 -> 2.5 | K42: =LT!L93 -> 10.69 | L42: =H42^F42 -> 0.783053 | M42: =1-L42 -> 0.216947 | N42: =N41*L41 -> 62551.203 | O42: =N42*M42 -> 13570.296 | P42: =(((-5/24)*O41)+((2.5)*O42)+((5/24)*O43))/O42 -> 2.585891 | Q42: =(C42*N43)+(P42*O42) -> 279995.84 | R42: =R43+Q42 -> 670315.61 | S42: =R42/N42 -> 10.716271 | T42: =S42-K42 -> 0.026270506
B43: 75 | C43: 5 | D43: ='Defunciones generales'!D94 -> 1411.1201 | E43: =Homicidios!D569 -> 2 | F43: =(D43-E43)/D43 -> 0.99858269 | G43: =LT!H94 -> 48964 | H43: =1-LT!F94 -> 0.671823 | I43: =1-H43 -> 0.328177 | J43: =LT!G94 -> 2.5 | K43: =LT!L94 -> 7.95 | L43: =H43^F43 -> 0.67220185 | M43: =1-L43 -> 0.32779815 | N43: =N42*L42 -> 48980.907 | O43: =N43*M43 -> 16055.851 | P43: =(((-5/24)*O42)+((2.5)*O43)+((5/24)*O44))/O43 -> 2.5390223 | Q43: =(C43*N44)+(P43*O43) -> 205391.44 | R43: =R44+Q43 -> 390319.77 | S43: =R43/N43 -> 7.9688146 | T43: =S43-K43 -> 0.018814649
...

Sheet LT
A1: lt_desc | B1: year | C1: sex | D1: age | E1: mx | F1: qx | G1: ax | H1: lx | I1: dx | J1: Lx | K1: Tx | L1: ex
A2: LT VR/Census, MEX | B2: 2010 | C2: m | D2: 0 | E2: 0.027048 | F2: 0.026417 | G2: 0.12 | H2: 100000 | I2: 2642 | J2: 97669 | K2: 6440382 | L2: 64.4
A3: LT VR/Census, MEX | B3: 2010 | C3: m | D3: 1 | E3: 0.001135 | F3: 0.004529 | G3: 1.57 | H3: 97358 | I3: 441 | J3: 388364 | K3: 6342713 | L3: 65.15
A4: LT VR/Census, MEX | B4: 2010 | C4: m | D4: 5 | E4: 0.000542 | F4: 0.002707 | G4: 2.5 | H4: 96917 | I4: 262 | J4: 483931 | K4: 5954349 | L4: 61.44
A5: LT VR/Census, MEX | B5: 2010 | C5: m | D5: 10 | E5: 0.000507 | F5: 0.002534 | G5: 2.5 | H5: 96655 | I5: 245 | J5: 482663 | K5: 5470418 | L5: 56.6
A6: LT VR/Census, MEX | B6: 2010 | C6: m | D6: 15 | E6: 0.00143 | F6: 0.007123 | G6: 2.5 | H6: 96410 | I6: 687 | J6: 480334 | K6: 4987755 | L6: 51.73
A7: LT VR/Census, MEX | B7: 2010 | C7: m | D7: 20 | E7: 0.002633 | F7: 0.013081 | G7: 2.5 | H7: 95723 | I7: 1252 | J7: 475487 | K7: 4507422 | L7: 47.09
A8: LT VR/Census, MEX | B8: 2010 | C8: m | D8: 25 | E8: 0.002869 | F8: 0.014242 | G8: 2.5 | H8: 94471 | I8: 1345 | J8: 468992 | K8: 4031935 | L8: 42.68
A9: LT VR/Census, MEX | B9: 2010 | C9: m | D9: 30 | E9: 0.003976 | F9: 0.019683 | G9: 2.5 | H9: 93126 | I9: 1833 | J9: 461046 | K9: 3562943 | L9: 38.26
A10: LT VR/Census, MEX | B10: 2010 | C10: m | D10: 35 | E10: 0.005121 | F10: 0.02528 | G10: 2.5 | H10: 91293 | I10: 2308 | J10: 450694 | K10: 3101896 | L10: 33.98
A11: LT VR/Census, MEX | B11: 2010 | C11: m | D11: 40 | E11: 0.007442 | F11: 0.036531 | G11: 2.5 | H11: 88985 | I11: 3251 | J11: 436797 | K11: 2651202 | L11: 29.79
A12: LT VR/Census, MEX | B12: 2010 | C12: m | D12: 45 | E12: 0.0102 | F12: 0.049734 | G12: 2.5 | H12: 85734 | I12: 4264 | J12: 418011 | K12: 2214405 | L12: 25.83
A13: LT VR/Census, MEX | B13: 2010 | C13: m | D13: 50 | E13: 0.013854 | F13: 0.066953 | G13: 2.5 | H13: 81470 | I13: 5455 | J13: 393715 | K13: 1796394 | L13: 22.05
... A19: LT VR/Census, MEX | B19: 2010 | C19: m | D19: 80 | E19: 0.178938 | F19: 0.618158 | G19: 2.5 | H19: 20627 | I19: 12751 | J19: 71257 | K19: 95672 | L19: 4.64
A20: LT VR/Census, MEX | B20: 2010 | C20: m | D20: 85 | E20: 0.3226 | F20: 1 | G20: NA | H20: 7876 | I20: 7876 | J20: 24415 | K20: 24415 | L20: 3.1
A21: LT VR/Census, MEX | B21: 2019 | C21: m | D21: 0 | E21: 0.023311 | F21: 0.022836 | G21: 0.11 | H21: 100000 | I21: 2284 | J21: 97962 | K21: 6492687 | L21: 64.93
A22: LT VR/Census, MEX | B22: 2019 | C22: m | D22: 1 | E22: 0.000929 | F22: 0.003709 | G22: 1.59 | H22: 97716 | I22: 362 | J22: 389991 | K22: 6394725 | L22: 65.44
A23: LT VR/Census, MEX | B23: 2019 | C23: m | D23: 5 | E23: 0.000383 | F23: 0.001915 | G23: 2.5 | H23: 97354 | I23: 186 | J23: 486304 | K23: 6004734 | L23: 61.68
A24: LT VR/Census, MEX | B24: 2019 | C24: m | D24: 10 | E24: 0.000491 | F24: 0.002451 | G24: 2.5 | H24: 97168 | I24: 238 | J24: 485242 | K24: 5518431 | L24: 56.79
A25: LT VR/Census, MEX | B25: 2019 | C25: m | D25: 15 | E25: 0.001329 | F25: 0.006621 | G25: 2.5 | H25: 96929 | I25: 642 | J25: 483042 | K25: 5033188 | L25: 51.93
A26: LT VR/Census, MEX | B26: 2019 | C26: m | D26: 20 | E26: 0.002411 | F26: 0.011983 | G26: 2.5 | H26: 96288 | I26: 1154 | J26: 478554 | K26: 4550146 | L26: 47.26
A27: LT VR/Census, MEX | B27: 2019 | C27: m | D27: 25 | E27: 0.003223 | F27: 0.015986 | G27: 2.5 | H27: 95134 | I27: 1521 | J27: 471867 | K27: 4071592 | L27: 42.8
A28: LT VR/Census, MEX | B28: 2019 | C28: m | D28: 30 | E28: 0.004134 | F28: 0.020458 | G28: 2.5 | H28: 93613 | I28: 1915 | J28: 463277 | K28: 3599725 | L28: 38.45
A29: LT VR/Census, MEX | B29: 2019 | C29: m | D29: 35 | E29: 0.005703 | F29: 0.028113 | G29: 2.5 | H29: 91698 | I29: 2578 | J29: 452044 | K29: 3136449 | L29: 34.2
A30: LT VR/Census, MEX | B30: 2019 | C30: m | D30: 40 | E30: 0.007204 | F30: 0.035382 | G30: 2.5 | H30: 89120 | I30: 3153 | J30: 437717 | K30: 2684404 | L30: 30.12
A31: LT VR/Census, MEX | B31: 2019 | C31: m | D31: 45 | E31: 0.009797 | F31: 0.047814 | G31: 2.5 | H31: 85967 | I31: 4110 | J31: 419557 | K31: 2246688 | L31: 26.13
A32: LT VR/Census, MEX | B32: 2019 | C32: m | D32: 50 | E32: 0.013881 | F32: 0.06708 | G32: 2.5 | H32: 81856 | I32: 5491 | J32: 395554 | K32: 1827130 | L32: 22.32
... A38: LT VR/Census, MEX | B38: 2019 | C38: m | D38: 80 | E38: 0.148757 | F38: 0.542161 | G38: 2.5 | H38: 22716 | I38: 12316 | J38: 82790 | K38: 117824 | L38: 5.19
A39: LT VR/Census, MEX | B39: 2019 | C39: m | D39: 85 | E39: 0.296861 | F39: 1 | G39: NA | H39: 10400 | I39: 10400 | J39: 35034 | K39: 35034 | L39: 3.37
A40: LT VR/Census, MEX | B40: 2021 | C40: m | D40: 0 | E40: 0.019123 | F40: 0.018798 | G40: 0.1 | H40: 100000 | I40: 1880 | J40: 98301 | K40: 6072202 | L40: 60.72
A41: LT VR/Census, MEX | B41: 2021 | C41: m | D41: 1 | E41: 0.001163 | F41: 0.00464 | G41: 1.6 | H41: 98120 | I41: 455 | J41: 391387 | K41: 5973901 | L41: 60.88
A42: LT VR/Census, MEX | B42: 2021 | C42: m | D42: 5 | E42: 0.000318 | F42: 0.00159 | G42: 2.5 | H42: 97665 | I42: 155 | J42: 487936 | K42: 5582514 | L42: 57.16
A43: LT VR/Census, MEX | B43: 2021 | C43: m | D43: 10 | E43: 0.000519 | F43: 0.002592 | G43: 2.5 | H43: 97510 | I43: 253 | J43: 486916 | K43: 5094578 | L43: 52.25
A44: LT VR/Census, MEX | B44: 2021 | C44: m | D44: 15 | E44: 0.001382 | F44: 0.006885 | G44: 2.5 | H44: 97257 | I44: 670 | J44: 484610 | K44: 4607662 | L44: 47.38
A45: LT VR/Census, MEX | B45: 2021 | C45: m | D45: 20 | E45: 0.003016 | F45: 0.014969 | G45: 2.5 | H45: 96587 | I45: 1446 | J45: 479322 | K45: 4123052 | L45: 42.69
A46: LT VR/Census, MEX | B46: 2021 | C46: m | D46: 25 | E46: 0.004413 | F46: 0.021824 | G46: 2.5 | H46: 95141 | I46: 2076 | J46: 470516 | K46: 3643730 | L46: 38.3
A47: LT VR/Census, MEX | B47: 2021 | C47: m | D47: 30 | E47: 0.005389 | F47: 0.026585 | G47: 2.5 | H47: 93065 | I47: 2474 | J47: 459140 | K47: 3173214 | L47: 34.1
A48: LT VR/Census, MEX | B48: 2021 | C48: m | D48: 35 | E48: 0.007802 | F48: 0.038262 | G48: 2.5 | H48: 90591 | I48: 3466 | J48: 444289 | K48: 2714074 | L48: 29.96
A49: LT VR/Census, MEX | B49: 2021 | C49: m | D49: 40 | E49: 0.010239 | F49: 0.049917 | G49: 2.5 | H49: 87125 | I49: 4349 | J49: 424751 | K49: 2269784 | L49: 26.05
A50: LT VR/Census, MEX | B50: 2021 | C50: m | D50: 45 | E50: 0.015867 | F50: 0.076309 | G50: 2.5 | H50: 82776 | I50: 6317 | J50: 398087 | K50: 1845033 | L50: 22.29
...

Sheet Homicidios
A1: year | B1: sex | C1: age | D1: deaths
A2: 1990 | B2: female | C2: 0 | D2: 0
A3: 1990 | B3: female | C3: 1 | D3: 0
A4: 1990 | B4: female | C4: 5 | D4: 0
A5: 1990 | B5: female | C5: 10 | D5: 0
A6: 1990 | B6: female | C6: 15 | D6: 0
A7: 1990 | B7: female | C7: 20 | D7: 2
A8: 1990 | B8: female | C8: 25 | D8: 2
A9: 1990 | B9: female | C9: 30 | D9: 0
A10: 1990 | B10: female | C10: 35 | D10: 2
A11: 1990 | B11: female | C11: 40 | D11: 2
A12: 1990 | B12: female | C12: 45 | D12: 4
A13: 1990 | B13: female | C13: 50 | D13: 2
... A1331: 2024 | B1331: male | C1331: 85 | D1331: 0

Sheet Defunciones generales
A1: year | B1: sex | C1: age | D1: deaths
A2: 2010 | B2: male | C2: 0 | D2: 452.66395
A3: 2010 | B3: male | C3: 1 | D3: 79.540877
A4: 2010 | B4: male | C4: 5 | D4: 50.137996
A5: 2010 | B5: male | C5: 10 | D5: 47.456526
A6: 2010 | B6: male | C6: 15 | D6: 139.04557
A7: 2010 | B7: male | C7: 20 | D7: 241.3009
A8: 2010 | B8: male | C8: 25 | D8: 226.61354
A9: 2010 | B9: male | C9: 30 | D9: 292.77488
A10: 2010 | B10: male | C10: 35 | D10: 360.94091
A11: 2010 | B11: male | C11: 40 | D11: 421.77279
A12: 2010 | B12: male | C12: 45 | D12: 498.6433
A13: 2010 | B13: male | C13: 50 | D13: 583.51111
... A115: 2021 | B115: female | C115: 85 | D115: 3430.4129
